<?xml version="1.0" encoding="UTF-8"?>
<sdf version='1.6'>
  <model name='fable_robot'>
    <pose>0 0 0 0 0 0</pose>

    <link name='world'>
    </link>
    <link name='base_link'>
      <pose frame=''>0 0 0 0 -0 0</pose>
      <inertial>
        <pose frame=''>0 0 0 0 -0 0</pose>
        <mass>1000</mass>
        <inertia>
          <ixx>0.000196919</ixx>
          <ixy>0</ixy>
          <ixz>0</ixz>
          <iyy>0.000196919</iyy>
          <iyz>0</iyz>
          <izz>0.000245</izz>
        </inertia>
      </inertial>
      <collision name='base_link_collision'>
        <pose frame=''>0 0 0 0 -0 0</pose>
        <geometry>
          <mesh>
            <scale>1 1 1</scale>
            <uri>model://fable_model/meshes/base.dae</uri>
          </mesh>
        </geometry>
        <surface>
          <contact>
            <ode/>
          </contact>
          <friction>
            <ode/>
          </friction>
        </surface>
      </collision>
      <visual name='base_link_visual'>
        <pose frame=''>0 0 0 0 -0 0</pose>
        <geometry>
          <mesh>
            <scale>1 1 1</scale>
            <uri>model://fable_model/meshes/base.dae</uri>
          </mesh>
        </geometry>
        <material>
          <script>
            <uri>__default__</uri>
            <name>__default__</name>
          </script>
        </material>
      </visual>
      <gravity>1</gravity>
      <velocity_decay/>
    </link>

    <joint name='world_joint' type='fixed'>
      <child>base_link</child>
      <parent>world</parent>
      <axis>
        <xyz>-0 0 0</xyz>
        <use_parent_model_frame>1</use_parent_model_frame>
      </axis>
    </joint>


    <link name='neck'>
      <pose frame=''>0 0 0.0945 1.57079 -1.57079 3.14159</pose>
      <inertial>
        <pose frame=''>0 0 0 0 -0 0</pose>
        <mass>0.01</mass>
        <inertia>
          <ixx>6.88121e-06</ixx>
          <ixy>-7.58338e-10</ixy>
          <ixz>-7.71885e-11</ixz>
          <iyy>7.67769e-06</iyy>
          <iyz>7.59082e-10</iyz>
          <izz>6.8812e-06</izz>
        </inertia>
      </inertial>
      <collision name='neck_collision'>
        <pose frame=''>-0.0112 0 0 -1.57 -1.57 0</pose>
        <geometry>
          <mesh>
            <scale>1 1 1</scale>
            <uri>model://fable_model/meshes/middle.dae</uri>
          </mesh>
        </geometry>
        <surface>
          <contact>
            <ode/>
          </contact>
          <friction>
            <ode/>
          </friction>
        </surface>
      </collision>
      <visual name='neck_visual'>
        <pose frame=''>-0.0112 0 0 -1.57 -1.57 0</pose>
        <geometry>
          <mesh>
            <scale>1 1 1</scale>
            <uri>model://fable_model/meshes/middle.dae</uri>
          </mesh>
        </geometry>
        <material>
          <script>
            <uri>__default__</uri>
            <name>__default__</name>
          </script>
        </material>
      </visual>
      <gravity>1</gravity>
      <velocity_decay/>
    </link>
    <joint name='joint_1' type='revolute'>
      <child>neck</child>
      <parent>base_link</parent>
      <axis>
        <xyz>-0 1 -0</xyz>
        <limit>
          <lower>-1.5708</lower>
          <upper>1.5708</upper>
          <effort>1.56</effort>
          <velocity>1.56</velocity>
        </limit>
        <dynamics>
          <damping>0.15</damping>
          <friction>0.1</friction>
          <spring_reference>0</spring_reference>
          <spring_stiffness>0</spring_stiffness>
        </dynamics>
        <use_parent_model_frame>1</use_parent_model_frame>
      </axis>
    </joint>
    <link name='top'>
      <pose frame=''>0 0 0.1402 3e-06 -1.57079 3.14159</pose>
      <inertial>
        <pose frame=''>0 0 0 0 -0 0</pose>
        <mass>0.1</mass>
        <inertia>
          <ixx>0.0001525</ixx>
          <ixy>0</ixy>
          <ixz>0</ixz>
          <iyy>0.0001525</iyy>
          <iyz>0</iyz>
          <izz>0.000245</izz>
        </inertia>
      </inertial>
      <collision name='top_collision'>
        <pose frame=''>0.0566 0 0 -1.57 0 1.57</pose>
        <geometry>
          <mesh>
            <scale>1 1 1</scale>
            <uri>model://fable_model/meshes/top.dae</uri>
          </mesh>
        </geometry>
        <surface>
          <contact>
            <ode/>
          </contact>
          <friction>
            <ode/>
          </friction>
        </surface>
      </collision>
      <collision name='top_fixed_joint_lump__ee_link_collision_1'>
        <pose frame=''>0.06 0 0 3.14159 1.57079 3.14159</pose>
        <geometry>
          <box>
            <size>0.01 0.01 0.01</size>
          </box>
        </geometry>
      </collision>
      <visual name='top_visual'>
        <pose frame=''>0.0566 0 0 -1.57 0 1.57</pose>
        <geometry>
          <mesh>
            <scale>1 1 1</scale>
            <uri>model://fable_model/meshes/top.dae</uri>
          </mesh>
        </geometry>
        <material>
          <script>
            <uri>__default__</uri>
            <name>__default__</name>
          </script>
        </material>
      </visual>
      <gravity>1</gravity>
      <velocity_decay/>
    </link>
    <joint name='joint_2' type='revolute'>
      <child>top</child>
      <parent>neck</parent>
      <axis>
        <xyz>1 0 -0</xyz>
        <limit>
          <lower>-1.5708</lower>
          <upper>1.5708</upper>
          <effort>1.56</effort>
          <velocity>1.56</velocity>
        </limit>
        <dynamics>
          <damping>0.15</damping>
          <friction>0.1</friction>
          <spring_reference>0</spring_reference>
          <spring_stiffness>0</spring_stiffness>
        </dynamics>
        <use_parent_model_frame>1</use_parent_model_frame>
      </axis>
    </joint>

    <plugin name='generic_controller' filename='libgeneric_controller_plugin.so'>
      <robotNamespace>/fable_robot</robotNamespace>
      <controller joint_name='joint_1'>
        <type>position</type>
        <pid>100.0 10.0 10.0</pid>
      </controller>

      <controller joint_name='joint_2'>
        <type>position</type>
        <pid>100.0 10.0 10.0</pid>
      </controller>

    </plugin>
  </model>
</sdf>
